Traceback (most recent call last):
  File "c:\users\justb\anaconda3\envs\python37\lib\site-packages\jupyter_cache\executors\utils.py", line 56, in single_nb_execution
    record_timing=False,
  File "c:\users\justb\anaconda3\envs\python37\lib\site-packages\nbclient\client.py", line 1112, in execute
    return NotebookClient(nb=nb, resources=resources, km=km, **kwargs).execute()
  File "c:\users\justb\anaconda3\envs\python37\lib\site-packages\nbclient\util.py", line 74, in wrapped
    return just_run(coro(*args, **kwargs))
  File "c:\users\justb\anaconda3\envs\python37\lib\site-packages\nbclient\util.py", line 53, in just_run
    return loop.run_until_complete(coro)
  File "c:\users\justb\anaconda3\envs\python37\lib\asyncio\base_events.py", line 587, in run_until_complete
    return future.result()
  File "c:\users\justb\anaconda3\envs\python37\lib\site-packages\nbclient\client.py", line 554, in async_execute
    cell, index, execution_count=self.code_cells_executed + 1
  File "c:\users\justb\anaconda3\envs\python37\lib\site-packages\nbclient\client.py", line 857, in async_execute_cell
    self._check_raise_for_error(cell, exec_reply)
  File "c:\users\justb\anaconda3\envs\python37\lib\site-packages\nbclient\client.py", line 760, in _check_raise_for_error
    raise CellExecutionError.from_cell_and_msg(cell, exec_reply_content)
nbclient.exceptions.CellExecutionError: An error occurred while executing the following cell:
------------------
print(np.dot(M2, M1))
------------------

[1;31m---------------------------------------------------------------------------[0m
[1;31mValueError[0m                                Traceback (most recent call last)
[1;32m<ipython-input-28-e2af9c921404>[0m in [0;36m<module>[1;34m[0m
[1;32m----> 1[1;33m [0mprint[0m[1;33m([0m[0mnp[0m[1;33m.[0m[0mdot[0m[1;33m([0m[0mM2[0m[1;33m,[0m [0mM1[0m[1;33m)[0m[1;33m)[0m[1;33m[0m[1;33m[0m[0m
[0m
[1;32m<__array_function__ internals>[0m in [0;36mdot[1;34m(*args, **kwargs)[0m

[1;31mValueError[0m: shapes (2,3) and (2,2) not aligned: 3 (dim 1) != 2 (dim 0)
ValueError: shapes (2,3) and (2,2) not aligned: 3 (dim 1) != 2 (dim 0)

