Traceback (most recent call last):
  File "c:\users\justb\anaconda3\envs\python37\lib\site-packages\jupyter_cache\executors\utils.py", line 56, in single_nb_execution
    record_timing=False,
  File "c:\users\justb\anaconda3\envs\python37\lib\site-packages\nbclient\client.py", line 1112, in execute
    return NotebookClient(nb=nb, resources=resources, km=km, **kwargs).execute()
  File "c:\users\justb\anaconda3\envs\python37\lib\site-packages\nbclient\util.py", line 74, in wrapped
    return just_run(coro(*args, **kwargs))
  File "c:\users\justb\anaconda3\envs\python37\lib\site-packages\nbclient\util.py", line 53, in just_run
    return loop.run_until_complete(coro)
  File "c:\users\justb\anaconda3\envs\python37\lib\asyncio\base_events.py", line 587, in run_until_complete
    return future.result()
  File "c:\users\justb\anaconda3\envs\python37\lib\site-packages\nbclient\client.py", line 554, in async_execute
    cell, index, execution_count=self.code_cells_executed + 1
  File "c:\users\justb\anaconda3\envs\python37\lib\site-packages\nbclient\client.py", line 857, in async_execute_cell
    self._check_raise_for_error(cell, exec_reply)
  File "c:\users\justb\anaconda3\envs\python37\lib\site-packages\nbclient\client.py", line 760, in _check_raise_for_error
    raise CellExecutionError.from_cell_and_msg(cell, exec_reply_content)
nbclient.exceptions.CellExecutionError: An error occurred while executing the following cell:
------------------
a = 5
b = 0
print(a / b)
------------------

[1;31m---------------------------------------------------------------------------[0m
[1;31mZeroDivisionError[0m                         Traceback (most recent call last)
[1;32m<ipython-input-8-dfcedec16dfc>[0m in [0;36m<module>[1;34m[0m
[0;32m      1[0m [0ma[0m [1;33m=[0m [1;36m5[0m[1;33m[0m[1;33m[0m[0m
[0;32m      2[0m [0mb[0m [1;33m=[0m [1;36m0[0m[1;33m[0m[1;33m[0m[0m
[1;32m----> 3[1;33m [0mprint[0m[1;33m([0m[0ma[0m [1;33m/[0m [0mb[0m[1;33m)[0m[1;33m[0m[1;33m[0m[0m
[0m
[1;31mZeroDivisionError[0m: division by zero
ZeroDivisionError: division by zero

